{
 "cells": [
  {
   "cell_type": "markdown",
   "metadata": {},
   "source": [
    "# Notebook to process data in SMCE helio-public S3 bucket using Dask\n",
    "\n",
    "### You will need to create the conda environment for this notebook, use 'environment-s3-demo.yml' with the command (in the terminal)\n",
    "### > conda env create -f environment-s3-dask-demo.yml\n",
    "\n",
    "### then make sure to select the 'conda env:s3-dask-demo' environment for this notebook!\n",
    "<hr>"
   ]
  },
  {
   "cell_type": "markdown",
   "metadata": {},
   "source": [
    "## First:  What is S3? \n",
    "\n",
    "S3 stands for \"Simple Storage Service,\" which provides object storage for for AWS.  https://aws.amazon.com/s3/ \n",
    "\n",
    "It allows people to query and access data from a common location reference.  The buckets can be made <a href=\"https://stackoverflow.com/q/16784052\">web accessible to users outside of daskhub</a> if web access is enabled.    \n",
    "\n",
    "S3 buckets are individual storage elements.  To <a href=\"https://awscli.amazonaws.com/v2/documentation/api/latest/reference/s3/ls.html\">get a list of the S3 buckets</a> on the SMCE Daskhub, enter this at a terminal prompt : <br>\n",
    "`aws s3 ls`\n",
    "\n",
    "\n",
    "To view the contents of a specific bucket, reference it with s3:// <br>\n",
    "`aws s3 ls s3://helio-public/`\n",
    ">            PRE SDO/\n",
    ">            PRE SOHO/\n",
    "\n",
    "(Note: \"PRE\" stands for prefix, so SDO/ is an AWS prefix with name SDO.) \n",
    "<hr>"
   ]
  },
  {
   "cell_type": "code",
   "execution_count": 6,
   "metadata": {},
   "outputs": [
    {
     "name": "stderr",
     "output_type": "stream",
     "text": [
      "Exception in callback None()\n",
      "handle: <Handle cancelled>\n",
      "Traceback (most recent call last):\n",
      "  File \"/srv/conda/envs/notebook/lib/python3.8/site-packages/tornado/iostream.py\", line 1391, in _do_ssl_handshake\n",
      "    self.socket.do_handshake()\n",
      "  File \"/srv/conda/envs/notebook/lib/python3.8/ssl.py\", line 1309, in do_handshake\n",
      "    self._sslobj.do_handshake()\n",
      "ssl.SSLCertVerificationError: [SSL: CERTIFICATE_VERIFY_FAILED] certificate verify failed: self signed certificate (_ssl.c:1125)\n",
      "\n",
      "During handling of the above exception, another exception occurred:\n",
      "\n",
      "Traceback (most recent call last):\n",
      "  File \"/srv/conda/envs/notebook/lib/python3.8/asyncio/events.py\", line 81, in _run\n",
      "    self._context.run(self._callback, *self._args)\n",
      "  File \"/srv/conda/envs/notebook/lib/python3.8/site-packages/tornado/platform/asyncio.py\", line 189, in _handle_events\n",
      "    handler_func(fileobj, events)\n",
      "  File \"/srv/conda/envs/notebook/lib/python3.8/site-packages/tornado/iostream.py\", line 696, in _handle_events\n",
      "    self._handle_read()\n",
      "  File \"/srv/conda/envs/notebook/lib/python3.8/site-packages/tornado/iostream.py\", line 1478, in _handle_read\n",
      "    self._do_ssl_handshake()\n",
      "  File \"/srv/conda/envs/notebook/lib/python3.8/site-packages/tornado/iostream.py\", line 1409, in _do_ssl_handshake\n",
      "    return self.close(exc_info=err)\n",
      "  File \"/srv/conda/envs/notebook/lib/python3.8/site-packages/tornado/iostream.py\", line 611, in close\n",
      "    self._signal_closed()\n",
      "  File \"/srv/conda/envs/notebook/lib/python3.8/site-packages/tornado/iostream.py\", line 641, in _signal_closed\n",
      "    self._ssl_connect_future.exception()\n",
      "asyncio.exceptions.CancelledError\n",
      "distributed.client - ERROR - Failed to reconnect to scheduler after 10.00 seconds, closing client\n",
      "distributed.client - ERROR - Failed to reconnect to scheduler after 10.00 seconds, closing client\n",
      "_GatheringFuture exception was never retrieved\n",
      "future: <_GatheringFuture finished exception=CancelledError()>\n",
      "asyncio.exceptions.CancelledError\n",
      "_GatheringFuture exception was never retrieved\n",
      "future: <_GatheringFuture finished exception=CancelledError()>\n",
      "asyncio.exceptions.CancelledError\n",
      "Exception in callback None()\n",
      "handle: <Handle cancelled>\n",
      "Traceback (most recent call last):\n",
      "  File \"/srv/conda/envs/notebook/lib/python3.8/site-packages/tornado/iostream.py\", line 1391, in _do_ssl_handshake\n",
      "    self.socket.do_handshake()\n",
      "  File \"/srv/conda/envs/notebook/lib/python3.8/ssl.py\", line 1309, in do_handshake\n",
      "    self._sslobj.do_handshake()\n",
      "ssl.SSLEOFError: EOF occurred in violation of protocol (_ssl.c:1125)\n",
      "\n",
      "During handling of the above exception, another exception occurred:\n",
      "\n",
      "Traceback (most recent call last):\n",
      "  File \"/srv/conda/envs/notebook/lib/python3.8/asyncio/events.py\", line 81, in _run\n",
      "    self._context.run(self._callback, *self._args)\n",
      "  File \"/srv/conda/envs/notebook/lib/python3.8/site-packages/tornado/platform/asyncio.py\", line 189, in _handle_events\n",
      "    handler_func(fileobj, events)\n",
      "  File \"/srv/conda/envs/notebook/lib/python3.8/site-packages/tornado/iostream.py\", line 696, in _handle_events\n",
      "    self._handle_read()\n",
      "  File \"/srv/conda/envs/notebook/lib/python3.8/site-packages/tornado/iostream.py\", line 1478, in _handle_read\n",
      "    self._do_ssl_handshake()\n",
      "  File \"/srv/conda/envs/notebook/lib/python3.8/site-packages/tornado/iostream.py\", line 1400, in _do_ssl_handshake\n",
      "    return self.close(exc_info=err)\n",
      "  File \"/srv/conda/envs/notebook/lib/python3.8/site-packages/tornado/iostream.py\", line 611, in close\n",
      "    self._signal_closed()\n",
      "  File \"/srv/conda/envs/notebook/lib/python3.8/site-packages/tornado/iostream.py\", line 641, in _signal_closed\n",
      "    self._ssl_connect_future.exception()\n",
      "asyncio.exceptions.CancelledError\n",
      "Exception in callback None()\n",
      "handle: <Handle cancelled>\n",
      "Traceback (most recent call last):\n",
      "  File \"/srv/conda/envs/notebook/lib/python3.8/site-packages/tornado/iostream.py\", line 1391, in _do_ssl_handshake\n",
      "    self.socket.do_handshake()\n",
      "  File \"/srv/conda/envs/notebook/lib/python3.8/ssl.py\", line 1309, in do_handshake\n",
      "    self._sslobj.do_handshake()\n",
      "ssl.SSLCertVerificationError: [SSL: CERTIFICATE_VERIFY_FAILED] certificate verify failed: self signed certificate (_ssl.c:1125)\n",
      "\n",
      "During handling of the above exception, another exception occurred:\n",
      "\n",
      "Traceback (most recent call last):\n",
      "  File \"/srv/conda/envs/notebook/lib/python3.8/asyncio/events.py\", line 81, in _run\n",
      "    self._context.run(self._callback, *self._args)\n",
      "  File \"/srv/conda/envs/notebook/lib/python3.8/site-packages/tornado/platform/asyncio.py\", line 189, in _handle_events\n",
      "    handler_func(fileobj, events)\n",
      "  File \"/srv/conda/envs/notebook/lib/python3.8/site-packages/tornado/iostream.py\", line 696, in _handle_events\n",
      "    self._handle_read()\n",
      "  File \"/srv/conda/envs/notebook/lib/python3.8/site-packages/tornado/iostream.py\", line 1478, in _handle_read\n",
      "    self._do_ssl_handshake()\n",
      "  File \"/srv/conda/envs/notebook/lib/python3.8/site-packages/tornado/iostream.py\", line 1409, in _do_ssl_handshake\n",
      "    return self.close(exc_info=err)\n",
      "  File \"/srv/conda/envs/notebook/lib/python3.8/site-packages/tornado/iostream.py\", line 611, in close\n",
      "    self._signal_closed()\n",
      "  File \"/srv/conda/envs/notebook/lib/python3.8/site-packages/tornado/iostream.py\", line 641, in _signal_closed\n",
      "    self._ssl_connect_future.exception()\n",
      "asyncio.exceptions.CancelledError\n",
      "Exception in callback None()\n",
      "handle: <Handle cancelled>\n",
      "Traceback (most recent call last):\n",
      "  File \"/srv/conda/envs/notebook/lib/python3.8/site-packages/tornado/iostream.py\", line 1391, in _do_ssl_handshake\n",
      "    self.socket.do_handshake()\n",
      "  File \"/srv/conda/envs/notebook/lib/python3.8/ssl.py\", line 1309, in do_handshake\n",
      "    self._sslobj.do_handshake()\n",
      "ssl.SSLCertVerificationError: [SSL: CERTIFICATE_VERIFY_FAILED] certificate verify failed: self signed certificate (_ssl.c:1125)\n",
      "\n",
      "During handling of the above exception, another exception occurred:\n",
      "\n",
      "Traceback (most recent call last):\n",
      "  File \"/srv/conda/envs/notebook/lib/python3.8/asyncio/events.py\", line 81, in _run\n",
      "    self._context.run(self._callback, *self._args)\n",
      "  File \"/srv/conda/envs/notebook/lib/python3.8/site-packages/tornado/platform/asyncio.py\", line 189, in _handle_events\n",
      "    handler_func(fileobj, events)\n",
      "  File \"/srv/conda/envs/notebook/lib/python3.8/site-packages/tornado/iostream.py\", line 696, in _handle_events\n",
      "    self._handle_read()\n",
      "  File \"/srv/conda/envs/notebook/lib/python3.8/site-packages/tornado/iostream.py\", line 1478, in _handle_read\n",
      "    self._do_ssl_handshake()\n",
      "  File \"/srv/conda/envs/notebook/lib/python3.8/site-packages/tornado/iostream.py\", line 1409, in _do_ssl_handshake\n",
      "    return self.close(exc_info=err)\n",
      "  File \"/srv/conda/envs/notebook/lib/python3.8/site-packages/tornado/iostream.py\", line 611, in close\n",
      "    self._signal_closed()\n",
      "  File \"/srv/conda/envs/notebook/lib/python3.8/site-packages/tornado/iostream.py\", line 641, in _signal_closed\n",
      "    self._ssl_connect_future.exception()\n",
      "asyncio.exceptions.CancelledError\n",
      "Exception in callback None()\n",
      "handle: <Handle cancelled>\n",
      "Traceback (most recent call last):\n",
      "  File \"/srv/conda/envs/notebook/lib/python3.8/site-packages/tornado/iostream.py\", line 1391, in _do_ssl_handshake\n",
      "    self.socket.do_handshake()\n",
      "  File \"/srv/conda/envs/notebook/lib/python3.8/ssl.py\", line 1309, in do_handshake\n",
      "    self._sslobj.do_handshake()\n",
      "ssl.SSLCertVerificationError: [SSL: CERTIFICATE_VERIFY_FAILED] certificate verify failed: self signed certificate (_ssl.c:1125)\n",
      "\n",
      "During handling of the above exception, another exception occurred:\n",
      "\n",
      "Traceback (most recent call last):\n",
      "  File \"/srv/conda/envs/notebook/lib/python3.8/asyncio/events.py\", line 81, in _run\n",
      "    self._context.run(self._callback, *self._args)\n",
      "  File \"/srv/conda/envs/notebook/lib/python3.8/site-packages/tornado/platform/asyncio.py\", line 189, in _handle_events\n",
      "    handler_func(fileobj, events)\n",
      "  File \"/srv/conda/envs/notebook/lib/python3.8/site-packages/tornado/iostream.py\", line 696, in _handle_events\n",
      "    self._handle_read()\n",
      "  File \"/srv/conda/envs/notebook/lib/python3.8/site-packages/tornado/iostream.py\", line 1478, in _handle_read\n",
      "    self._do_ssl_handshake()\n",
      "  File \"/srv/conda/envs/notebook/lib/python3.8/site-packages/tornado/iostream.py\", line 1409, in _do_ssl_handshake\n",
      "    return self.close(exc_info=err)\n",
      "  File \"/srv/conda/envs/notebook/lib/python3.8/site-packages/tornado/iostream.py\", line 611, in close\n",
      "    self._signal_closed()\n",
      "  File \"/srv/conda/envs/notebook/lib/python3.8/site-packages/tornado/iostream.py\", line 641, in _signal_closed\n",
      "    self._ssl_connect_future.exception()\n",
      "asyncio.exceptions.CancelledError\n",
      "Exception in callback None()\n",
      "handle: <Handle cancelled>\n",
      "Traceback (most recent call last):\n",
      "  File \"/srv/conda/envs/notebook/lib/python3.8/site-packages/tornado/iostream.py\", line 1391, in _do_ssl_handshake\n",
      "    self.socket.do_handshake()\n",
      "  File \"/srv/conda/envs/notebook/lib/python3.8/ssl.py\", line 1309, in do_handshake\n",
      "    self._sslobj.do_handshake()\n",
      "ssl.SSLCertVerificationError: [SSL: CERTIFICATE_VERIFY_FAILED] certificate verify failed: self signed certificate (_ssl.c:1125)\n",
      "\n",
      "During handling of the above exception, another exception occurred:\n",
      "\n",
      "Traceback (most recent call last):\n",
      "  File \"/srv/conda/envs/notebook/lib/python3.8/asyncio/events.py\", line 81, in _run\n",
      "    self._context.run(self._callback, *self._args)\n",
      "  File \"/srv/conda/envs/notebook/lib/python3.8/site-packages/tornado/platform/asyncio.py\", line 189, in _handle_events\n",
      "    handler_func(fileobj, events)\n",
      "  File \"/srv/conda/envs/notebook/lib/python3.8/site-packages/tornado/iostream.py\", line 696, in _handle_events\n",
      "    self._handle_read()\n",
      "  File \"/srv/conda/envs/notebook/lib/python3.8/site-packages/tornado/iostream.py\", line 1478, in _handle_read\n",
      "    self._do_ssl_handshake()\n",
      "  File \"/srv/conda/envs/notebook/lib/python3.8/site-packages/tornado/iostream.py\", line 1409, in _do_ssl_handshake\n",
      "    return self.close(exc_info=err)\n",
      "  File \"/srv/conda/envs/notebook/lib/python3.8/site-packages/tornado/iostream.py\", line 611, in close\n",
      "    self._signal_closed()\n",
      "  File \"/srv/conda/envs/notebook/lib/python3.8/site-packages/tornado/iostream.py\", line 641, in _signal_closed\n",
      "    self._ssl_connect_future.exception()\n",
      "asyncio.exceptions.CancelledError\n",
      "Exception in callback None()\n",
      "handle: <Handle cancelled>\n",
      "Traceback (most recent call last):\n",
      "  File \"/srv/conda/envs/notebook/lib/python3.8/site-packages/tornado/iostream.py\", line 1391, in _do_ssl_handshake\n",
      "    self.socket.do_handshake()\n",
      "  File \"/srv/conda/envs/notebook/lib/python3.8/ssl.py\", line 1309, in do_handshake\n",
      "    self._sslobj.do_handshake()\n",
      "ssl.SSLCertVerificationError: [SSL: CERTIFICATE_VERIFY_FAILED] certificate verify failed: self signed certificate (_ssl.c:1125)\n",
      "\n",
      "During handling of the above exception, another exception occurred:\n",
      "\n",
      "Traceback (most recent call last):\n",
      "  File \"/srv/conda/envs/notebook/lib/python3.8/asyncio/events.py\", line 81, in _run\n",
      "    self._context.run(self._callback, *self._args)\n",
      "  File \"/srv/conda/envs/notebook/lib/python3.8/site-packages/tornado/platform/asyncio.py\", line 189, in _handle_events\n",
      "    handler_func(fileobj, events)\n",
      "  File \"/srv/conda/envs/notebook/lib/python3.8/site-packages/tornado/iostream.py\", line 696, in _handle_events\n",
      "    self._handle_read()\n",
      "  File \"/srv/conda/envs/notebook/lib/python3.8/site-packages/tornado/iostream.py\", line 1478, in _handle_read\n",
      "    self._do_ssl_handshake()\n",
      "  File \"/srv/conda/envs/notebook/lib/python3.8/site-packages/tornado/iostream.py\", line 1409, in _do_ssl_handshake\n",
      "    return self.close(exc_info=err)\n",
      "  File \"/srv/conda/envs/notebook/lib/python3.8/site-packages/tornado/iostream.py\", line 611, in close\n",
      "    self._signal_closed()\n",
      "  File \"/srv/conda/envs/notebook/lib/python3.8/site-packages/tornado/iostream.py\", line 641, in _signal_closed\n",
      "    self._ssl_connect_future.exception()\n",
      "asyncio.exceptions.CancelledError\n"
     ]
    }
   ],
   "source": [
    "import boto3\n",
    "import s3fs\n",
    "import logging\n",
    "import dask\n",
    "from os import listdir\n",
    "from os.path import isfile, join\n",
    "\n",
    "from re import search\n",
    "\n",
    "from astropy.io import fits\n",
    "import io"
   ]
  },
  {
   "cell_type": "markdown",
   "metadata": {},
   "source": [
    "### 0. Configuration "
   ]
  },
  {
   "cell_type": "code",
   "execution_count": 2,
   "metadata": {},
   "outputs": [],
   "source": [
    "# name of the bucket to upload to\n",
    "bucket_name = 'helio-public'\n",
    "\n",
    "# location in the bucket to use\n",
    "bucket_path = '/SDO/AIA/'"
   ]
  },
  {
   "cell_type": "markdown",
   "metadata": {},
   "source": [
    "### Initialize the cluster and assign the client to the cluster, display the cluster widget"
   ]
  },
  {
   "cell_type": "code",
   "execution_count": 3,
   "metadata": {},
   "outputs": [
    {
     "data": {
      "application/vnd.jupyter.widget-view+json": {
       "model_id": "b0f478083b214a7dbb6856e0453eeeef",
       "version_major": 2,
       "version_minor": 0
      },
      "text/plain": [
       "VBox(children=(HTML(value='<h2>Cluster Options</h2>'), GridBox(children=(HTML(value=\"<p style='font-weight: bo…"
      ]
     },
     "metadata": {},
     "output_type": "display_data"
    }
   ],
   "source": [
    "from dask_gateway import Gateway, GatewayCluster\n",
    "gateway = Gateway()\n",
    "options = gateway.cluster_options()\n",
    "\n",
    "# We're setting some defaults here just for grins... \n",
    "# I like the pangeo/base-notebook image for the workers since it has almost every library you'd need on a worker\n",
    "# In our environment, without setting these, the widget will default to the same image that the notebook itself is running, \n",
    "# as well as 2 cores and 4GB memory per worker\n",
    "\n",
    "options.worker_cores=2\n",
    "options.worker_memory=1\n",
    "options"
   ]
  },
  {
   "cell_type": "code",
   "execution_count": 4,
   "metadata": {},
   "outputs": [
    {
     "data": {
      "application/vnd.jupyter.widget-view+json": {
       "model_id": "b80e2f3ecb9442c185447ef37ffc5815",
       "version_major": 2,
       "version_minor": 0
      },
      "text/plain": [
       "VBox(children=(HTML(value='<h2>GatewayCluster</h2>'), HBox(children=(HTML(value='\\n<div>\\n<style scoped>\\n    …"
      ]
     },
     "metadata": {},
     "output_type": "display_data"
    }
   ],
   "source": [
    "cluster = gateway.new_cluster(options)\n",
    "client = cluster.get_client()\n",
    "\n",
    "# manual scaling (2 workers)\n",
    "# cluster.scale(2)\n",
    "\n",
    "# Adaptively scale between 2 and 10 workers\n",
    "# cluster.adapt(minimum=2, maximum=10)\n",
    "\n",
    "cluster"
   ]
  },
  {
   "cell_type": "code",
   "execution_count": 5,
   "metadata": {},
   "outputs": [
    {
     "data": {
      "text/html": [
       "<table style=\"border: 2px solid white;\">\n",
       "<tr>\n",
       "<td style=\"vertical-align: top; border: 0px solid white\">\n",
       "<h3 style=\"text-align: left;\">Client</h3>\n",
       "<ul style=\"text-align: left; list-style: none; margin: 0; padding: 0;\">\n",
       "  <li><b>Scheduler: </b>gateway://traefik-daskhub-dask-gateway.daskhub:80/daskhub.ab39e1f3801548bdb39b023a59919f1c</li>\n",
       "  <li><b>Dashboard: </b><a href='/services/dask-gateway/clusters/daskhub.ab39e1f3801548bdb39b023a59919f1c/status' target='_blank'>/services/dask-gateway/clusters/daskhub.ab39e1f3801548bdb39b023a59919f1c/status</a></li>\n",
       "</ul>\n",
       "</td>\n",
       "<td style=\"vertical-align: top; border: 0px solid white\">\n",
       "<h3 style=\"text-align: left;\">Cluster</h3>\n",
       "<ul style=\"text-align: left; list-style:none; margin: 0; padding: 0;\">\n",
       "  <li><b>Workers: </b>0</li>\n",
       "  <li><b>Cores: </b>0</li>\n",
       "  <li><b>Memory: </b>0 B</li>\n",
       "</ul>\n",
       "</td>\n",
       "</tr>\n",
       "</table>"
      ],
      "text/plain": [
       "<Client: 'tls://192.168.17.192:8786' processes=0 threads=0, memory=0 B>"
      ]
     },
     "execution_count": 5,
     "metadata": {},
     "output_type": "execute_result"
    }
   ],
   "source": [
    "from dask.distributed import Client\n",
    "\n",
    "client = Client(cluster)\n",
    "client"
   ]
  },
  {
   "cell_type": "markdown",
   "metadata": {},
   "source": [
    "### Define routine pull data from bucket into memory and work with it"
   ]
  },
  {
   "cell_type": "code",
   "execution_count": 7,
   "metadata": {},
   "outputs": [],
   "source": [
    "# initialize connection to S3 bucket\n",
    "s3_client = boto3.resource('s3')\n",
    "bucket = s3_client.Bucket(bucket_name)"
   ]
  },
  {
   "cell_type": "code",
   "execution_count": 8,
   "metadata": {},
   "outputs": [
    {
     "data": {
      "text/plain": [
       "'SDO/AIA/AIA_L4_20141018_000001_94.fits'"
      ]
     },
     "execution_count": 8,
     "metadata": {},
     "output_type": "execute_result"
    }
   ],
   "source": [
    "# get our list of files/s3 objects\n",
    "\n",
    "# Iterates through all the objects, doing the pagination for you. Each obj\n",
    "# is an ObjectSummary, so it doesn't contain the body. You'll need to call\n",
    "# get to get the whole body.\n",
    "s3_files = []\n",
    "for obj in bucket.objects.all():\n",
    "    key = obj.key\n",
    "\n",
    "    if search ('fits', key):\n",
    "        s3_files.append(obj.key)\n",
    "\n",
    "s3_files[0]"
   ]
  },
  {
   "cell_type": "code",
   "execution_count": 15,
   "metadata": {},
   "outputs": [],
   "source": [
    "def open_fits_s3 (s3_key, bucket_name:str):\n",
    "     \n",
    "    fs = s3fs.S3FileSystem(anon=True)\n",
    "    with fs.open(bucket_name+'/'+s3_files[0], 'rb') as f:\n",
    "        fits_hdul = fits.open(io.BytesIO(f.read()))\n",
    "        fits_hdul.info()\n",
    "        return fits_hdul\n",
    "\n",
    "    return None\n",
    "    \n",
    "def work_on_data (client:dask.distributed.client.Client, bucket_name:str, files:list=[])->int:\n",
    "    \n",
    "    # Iterates through all the objects, doing the pagination for you. \n",
    "    hdu_list = client.map(open_fits_s3, files, bucket_name=bucket_name)\n",
    "    # print(f'HDU list: %s' % hdu_list)\n",
    "        \n",
    "    # <DO MORE WORK WITH FILE HERE>\n",
    "    \n",
    "    # return a status of some kind\n",
    "    return hdu_list\n"
   ]
  },
  {
   "cell_type": "code",
   "execution_count": 16,
   "metadata": {},
   "outputs": [
    {
     "name": "stdout",
     "output_type": "stream",
     "text": [
      "HDU list: [<Future: pending, key: open_fits_s3-ed7db6d246fa3f86388bf936098a3eb6>, <Future: pending, key: open_fits_s3-e79e2a0d6e5e1754e534ef77597a71ff>]\n",
      "<Client: 'tls://192.168.3.157:8786' processes=2 threads=4, memory=2.15 GB> [<Future: pending, key: open_fits_s3-ed7db6d246fa3f86388bf936098a3eb6>, <Future: pending, key: open_fits_s3-e79e2a0d6e5e1754e534ef77597a71ff>]\n",
      "HDU list: [<Future: pending, key: open_fits_s3-470053d25faf4048510298020903d400>, <Future: pending, key: open_fits_s3-35f1103f940b0fc48f74bd20bd9e1d47>]\n",
      "<Client: 'tls://192.168.3.157:8786' processes=2 threads=4, memory=2.15 GB> [<Future: pending, key: open_fits_s3-470053d25faf4048510298020903d400>, <Future: pending, key: open_fits_s3-35f1103f940b0fc48f74bd20bd9e1d47>]\n"
     ]
    }
   ],
   "source": [
    "def chunks(lst, n):\n",
    "    n = max(1, n)\n",
    "    return (lst[i:i+n] for i in range(0, len(lst), n))\n",
    "\n",
    "batch_size = 2\n",
    "for files_to_process in chunks(s3_files[:4], batch_size):\n",
    "\n",
    "    r = work_on_data(client, bucket_name, files_to_process)\n",
    "    print (client, r)\n"
   ]
  },
  {
   "cell_type": "code",
   "execution_count": null,
   "metadata": {},
   "outputs": [],
   "source": []
  }
 ],
 "metadata": {
  "kernelspec": {
   "display_name": "Python 3",
   "language": "python",
   "name": "python3"
  },
  "language_info": {
   "codemirror_mode": {
    "name": "ipython",
    "version": 3
   },
   "file_extension": ".py",
   "mimetype": "text/x-python",
   "name": "python",
   "nbconvert_exporter": "python",
   "pygments_lexer": "ipython3",
   "version": "3.8.8"
  }
 },
 "nbformat": 4,
 "nbformat_minor": 4
}
